<?xml version="1.0" encoding="utf-8"?>
<!-- This URDF was automatically created by SolidWorks to URDF Exporter! Originally created by Stephen Brawner (brawner@gmail.com) 
     Commit Version: 1.6.0-1-g15f4949  Build Version: 1.6.7594.29634
     For more information, please see http://wiki.ros.org/sw_urdf_exporter -->
<robot
  name="drone_description">
  <link
    name="base_link">
    <inertial>
      <origin
        xyz="5.7334E-07 0.026879 0.015324"
        rpy="0 0 0" />
      <mass
        value="0.38016" />
      <inertia
        ixx="0.00029212"
        ixy="-1.331E-09"
        ixz="-3.9126E-08"
        iyy="0.00040699"
        iyz="1.6869E-06"
        izz="0.00015798" />
    </inertial>
    <visual>
      <origin
        xyz="0 0 0"
        rpy="0 0 0" />
      <geometry>
        <mesh
          filename="package://drone_description/meshes/base_link.STL" />
      </geometry>
      <material
        name="">
        <color
          rgba="0.69804 0.69804 0.69804 1" />
      </material>
    </visual>
    <collision>
      <origin
        xyz="0 0 0"
        rpy="0 0 0" />
      <geometry>
        <mesh
          filename="package://drone_description/meshes/base_link.STL" />
      </geometry>
    </collision>
  </link>
  <link
    name="front_left_prop">
    <inertial>
      <origin
        xyz="4.1633E-17 -9.7145E-17 0.0089339"
        rpy="0 0 0" />
      <mass
        value="0.06804" />
      <inertia
        ixx="5.4455E-05"
        ixy="2.3822E-05"
        ixz="5.9768E-17"
        iyy="1.2182E-05"
        iyz="7.3605E-18"
        izz="6.5653E-05" />
    </inertial>
    <visual>
      <origin
        xyz="0 0 0"
        rpy="0 0 0" />
      <geometry>
        <mesh
          filename="package://drone_description/meshes/propeller.STL" />
      </geometry>
      <material
        name="">
        <color
          rgba="0.69804 0.69804 0.69804 1" />
      </material>
    </visual>
    <collision>
      <origin
        xyz="0 0 0"
        rpy="0 0 0" />
      <geometry>
        <mesh
          filename="package://drone_description/meshes/propeller.STL" />
      </geometry>
    </collision>
  </link>
  <joint
    name="front_left_prop_joint"
    type="continuous">
    <origin
      xyz="-0.092959 0.073449 0.0385"
      rpy="0 0 0" />
    <parent
      link="base_link" />
    <child
      link="front_left_prop" />
    <axis
      xyz="0 0 -1" />
  </joint>
  <link
    name="front_right_prop">
    <inertial>
      <origin
        xyz="-1.1102E-16 2.7756E-17 0.0089339"
        rpy="0 0 0" />
      <mass
        value="0.06804" />
      <inertia
        ixx="2.7327E-05"
        ixy="3.1279E-05"
        ixz="2.8419E-17"
        iyy="3.931E-05"
        iyz="7.026E-18"
        izz="6.5653E-05" />
    </inertial>
    <visual>
      <origin
        xyz="0 0 0"
        rpy="0 0 0" />
      <geometry>
        <mesh
          filename="package://drone_description/meshes/propeller.STL" />
      </geometry>
      <material
        name="">
        <color
          rgba="0.69804 0.69804 0.69804 1" />
      </material>
    </visual>
    <collision>
      <origin
        xyz="0 0 0"
        rpy="0 0 0" />
      <geometry>
        <mesh
          filename="package://drone_description/meshes/propeller.STL" />
      </geometry>
    </collision>
  </link>
  <joint
    name="front_right_prop_joint"
    type="continuous">
    <origin
      xyz="0.092959 0.073449 0.0385"
      rpy="0 0 0" />
    <parent
      link="base_link" />
    <child
      link="front_right_prop" />
    <axis
      xyz="0 0 -1" />
  </joint>
  <link
    name="back_left_prop">
    <inertial>
      <origin
        xyz="2.0817E-16 3.4694E-16 0.0089339"
        rpy="0 0 0" />
      <mass
        value="0.06804" />
      <inertia
        ixx="6.3793E-05"
        ixy="-9.2508E-06"
        ixz="6.1802E-19"
        iyy="2.8445E-06"
        iyz="1.2821E-17"
        izz="6.5653E-05" />
    </inertial>
    <visual>
      <origin
        xyz="0 0 0"
        rpy="0 0 0" />
      <geometry>
        <mesh
          filename="package://drone_description/meshes/propeller.STL" />
      </geometry>
      <material
        name="">
        <color
          rgba="0.69804 0.69804 0.69804 1" />
      </material>
    </visual>
    <collision>
      <origin
        xyz="0 0 0"
        rpy="0 0 0" />
      <geometry>
        <mesh
          filename="package://drone_description/meshes/propeller.STL" />
      </geometry>
    </collision>
  </link>
  <joint
    name="back_left_prop_joint"
    type="continuous">
    <origin
      xyz="-0.093338 -0.10988 0.0385"
      rpy="0 0 0" />
    <parent
      link="base_link" />
    <child
      link="back_left_prop" />
    <axis
      xyz="0 0 -1" />
  </joint>
  <link
    name="back_right_prop">
    <inertial>
      <origin
        xyz="3.8858E-16 3.4694E-16 0.0089339"
        rpy="0 0 0" />
      <mass
        value="0.06804" />
      <inertia
        ixx="5.9924E-05"
        ixy="-1.7504E-05"
        ixz="2.4088E-17"
        iyy="6.7129E-06"
        iyz="5.7361E-17"
        izz="6.5653E-05" />
    </inertial>
    <visual>
      <origin
        xyz="0 0 0"
        rpy="0 0 0" />
      <geometry>
        <mesh
          filename="package://drone_description/meshes/propeller.STL" />
      </geometry>
      <material
        name="">
        <color
          rgba="0.69804 0.69804 0.69804 1" />
      </material>
    </visual>
    <collision>
      <origin
        xyz="0 0 0"
        rpy="0 0 0" />
      <geometry>
        <mesh
          filename="package://drone_description/meshes/propeller.STL" />
      </geometry>
    </collision>
  </link>
  <joint
    name="back_right_prop"
    type="continuous">
    <origin
      xyz="0.093338 -0.10988 0.0385"
      rpy="0 0 0" />
    <parent
      link="base_link" />
    <child
      link="back_right_prop" />
    <axis
      xyz="0 0 -1" />
  </joint>
  <link
    name="camera">
    <inertial>
      <origin
        xyz="-0.0036143 0.00349 0.00925"
        rpy="0 0 0" />
      <mass
        value="0.090718" />
      <inertia
        ixx="2.4903E-06"
        ixy="3.2829E-09"
        ixz="8.2525E-22"
        iyy="3.279E-06"
        iyz="-1.531E-21"
        izz="2.3388E-06" />
    </inertial>
    <visual>
      <origin
        xyz="0 0 0"
        rpy="0 0 0" />
      <geometry>
        <mesh
          filename="package://drone_description/meshes/camera.STL" />
      </geometry>
      <material
        name="">
        <color
          rgba="0.69804 0.69804 0.69804 1" />
      </material>
    </visual>
    <collision>
      <origin
        xyz="0 0 0"
        rpy="0 0 0" />
      <geometry>
        <mesh
          filename="package://drone_description/meshes/camera.STL" />
      </geometry>
    </collision>
  </link>
  <joint
    name="camera_joint"
    type="revolute">
    <origin
      xyz="0.00925 0.059965 0.0165"
      rpy="1.5708 0 -1.5708" />
    <parent
      link="base_link" />
    <child
      link="camera" />
    <axis
      xyz="0 0 -1" />
    <limit
      lower="0"
      upper="0"
      effort="0"
      velocity="0" />
  </joint>
</robot>
