<?xml version="1.0"?>
<robot xmlns:xacro="http://www.ros.org/wiki/xacro">
  <xacro:macro name="prop_link" params="name">
    <link name="${name}">
      <inertial>
        <origin xyz="0 0 0.0089339" rpy="0 0 0" />
        <mass value="0.06804" />
        <inertia ixx="5.4455E-05" ixy="2.3822E-05" ixz="0" iyy="1.2182E-05" iyz="0" izz="6.5653E-05" />
      </inertial>
      <visual>
        <origin xyz="0 0 0" rpy="0 0 0" />
        <geometry>
          <mesh filename="package://drone_description/meshes/propeller.STL" />
        </geometry>
        <material name="">
          <color rgba="0.69804 0.69804 0.69804 1" />
        </material>
      </visual>
      <collision>
        <origin xyz="0 0 0" rpy="0 0 0" />
        <geometry>
          <mesh filename="package://drone_description/meshes/propeller.STL" />
        </geometry>
      </collision>
    </link>
  </xacro:macro>

  <xacro:macro name="prop_joint" params="name originxyz axis">
    <joint name="${name}_joint" type="continuous">
      <origin xyz="${originxyz}" rpy="0 0 0" />
      <parent link="base_link" />
      <child link="${name}" />
      <axis xyz="${axis}" />
    </joint>
  </xacro:macro>

  <xacro:macro name="prop_transmission" params="name">
    <transmission name="${name}_trans">
      <type>transmission_interface/SimpleTransmission</type>
      <joint name="${name}_joint">
        <hardwareInterface>hardware_interface/VelocityJointInterface</hardwareInterface>
      </joint>
      <actuator name="${name}_motor">
        <mechanicalReduction>1</mechanicalReduction>
        <hardwareInterface>hardware_interface/VelocityJointInterface</hardwareInterface>
      </actuator>
    </transmission>
  </xacro:macro>

  <!-- <transmission name="camera">
    <type>transmission_interface/SimpleTransmission</type>
    <joint name="camera_joint">
      <hardwareInterface>hardware_interface/PositionJointInterface</hardwareInterface>
    </joint>
    <actuator name="camera_motor">
      <mechanicalReduction>1</mechanicalReduction>
      <hardwareInterface>hardware_interface/PositionJointInterface</hardwareInterface>
    </actuator>
  </transmission> -->
</robot>
