<?xml version="1.0" ?>
<!-- =================================================================================== -->
<!-- |    This document was autogenerated by xacro from drone_base.xacro               | -->
<!-- |    EDITING THIS FILE BY HAND IS NOT RECOMMENDED                                 | -->
<!-- =================================================================================== -->
<robot name="drone_description">
  <!-- <transmission name="camera">
    <type>transmission_interface/SimpleTransmission</type>
    <joint name="camera_joint">
      <hardwareInterface>hardware_interface/PositionJointInterface</hardwareInterface>
    </joint>
    <actuator name="camera_motor">
      <mechanicalReduction>1</mechanicalReduction>
      <hardwareInterface>hardware_interface/PositionJointInterface</hardwareInterface>
    </actuator>
  </transmission> -->
  <!-- ROS CONTROL -->
  <gazebo>
    <plugin filename="libgazebo_ros_control.so" name="gazebo_ros_control">
      <robotNamespace>/</robotNamespace>
    </plugin>
  </gazebo>
  <!-- CAMERA -->
  <gazebo reference="camera">
    <sensor name="camera" type="camera">
      <update_rate>30.0</update_rate>
      <camera name="head">
        <horizontal_fov>1.3962634</horizontal_fov>
        <image>
          <width>1280</width>
          <height>720</height>
          <format>R8G8B8</format>
        </image>
        <clip>
          <near>0.02</near>
          <far>300</far>
        </clip>
        <noise>
          <type>gaussian</type>
          <!-- Noise is sampled independently per pixel on each frame.
              That pixel's noise value is added to each of its color
              channels, which at that point lie in the range [0,1]. -->
          <mean>0.0</mean>
          <stddev>0.007</stddev>
        </noise>
      </camera>
      <plugin filename="libgazebo_ros_camera.so" name="camera_controller">
        <alwaysOn>true</alwaysOn>
        <updateRate>0.0</updateRate>
        <cameraName>/camera</cameraName>
        <imageTopicName>image_raw</imageTopicName>
        <cameraInfoTopicName>camera_info</cameraInfoTopicName>
        <frameName>camera_link</frameName>
        <hackBaseline>0.07</hackBaseline>
        <distortionK1>0.0</distortionK1>
        <distortionK2>0.0</distortionK2>
        <distortionK3>0.0</distortionK3>
        <distortionT1>0.0</distortionT1>
        <distortionT2>0.0</distortionT2>
      </plugin>
    </sensor>
  </gazebo>
  <gazebo name="front_left_prop_joint">
    <provideFeedback>true</provideFeedback>
  </gazebo>
  <gazebo>
    <plugin filename="libgazebo_ros_ft_sensor.so" name="ft_sensor">
      <updateRate>100.0</updateRate>
      <topicName>prop1_sensor</topicName>
      <jointName>front_left_prop_joint</jointName>
    </plugin>
  </gazebo>
  <!-- DUMMY lINK -->
  <link name="dummy_link"/>
  <!-- LINKS -->
  <link name="base_link">
    <inertial>
      <origin rpy="0 0 0" xyz="5.7334E-07 0.026879 0.015324"/>
      <mass value="0.38016"/>
      <inertia ixx="0.00029212" ixy="-1.331E-09" ixz="-3.9126E-08" iyy="0.00040699" iyz="1.6869E-06" izz="0.00015798"/>
    </inertial>
    <visual>
      <origin rpy="0 0 0" xyz="0 0 0"/>
      <geometry>
        <mesh filename="package://drone_description/meshes/base_link.STL"/>
      </geometry>
      <material name="">
        <color rgba="0.69804 0.69804 0.69804 1"/>
      </material>
    </visual>
    <collision>
      <origin rpy="0 0 0" xyz="0 0 0"/>
      <geometry>
        <mesh filename="package://drone_description/meshes/base_link.STL"/>
      </geometry>
    </collision>
  </link>
  <link name="camera">
    <inertial>
      <origin rpy="0 0 0" xyz="-0.0036143 0.00349 0.00925"/>
      <mass value="0.090718"/>
      <inertia ixx="2.4903E-06" ixy="3.2829E-09" ixz="8.2525E-22" iyy="3.279E-06" iyz="-1.531E-21" izz="2.3388E-06"/>
    </inertial>
    <visual>
      <origin rpy="0 0 0" xyz="0 0 0"/>
      <geometry>
        <mesh filename="package://drone_description/meshes/camera.STL"/>
      </geometry>
      <material name="">
        <color rgba="0.69804 0.69804 0.69804 1"/>
      </material>
    </visual>
    <collision>
      <origin rpy="0 0 0" xyz="0 0 0"/>
      <geometry>
        <mesh filename="package://drone_description/meshes/camera.STL"/>
      </geometry>
    </collision>
  </link>
  <!-- DUMMY JOINT -->
  <joint name="dummy" type="fixed">
    <parent link="dummy_link"/>
    <child link="base_link"/>
  </joint>
  <!-- JOINT -->
  <joint name="camera_joint" type="revolute">
    <origin rpy="1.570796326795 0 -1.570796326795" xyz="0.00925 0.059965 0.0165"/>
    <parent link="base_link"/>
    <child link="camera"/>
    <axis xyz="0 0 -1"/>
    <limit effort="0" lower="-1.0471975511966667" upper="0" velocity="0"/>
  </joint>
  <link name="front_left_prop">
    <inertial>
      <origin rpy="0 0 0" xyz="0 0 0.0089339"/>
      <mass value="0.06804"/>
      <inertia ixx="5.4455E-05" ixy="2.3822E-05" ixz="0" iyy="1.2182E-05" iyz="0" izz="6.5653E-05"/>
    </inertial>
    <visual>
      <origin rpy="0 0 0" xyz="0 0 0"/>
      <geometry>
        <mesh filename="package://drone_description/meshes/propeller.STL"/>
      </geometry>
      <material name="">
        <color rgba="0.69804 0.69804 0.69804 1"/>
      </material>
    </visual>
    <collision>
      <origin rpy="0 0 0" xyz="0 0 0"/>
      <geometry>
        <mesh filename="package://drone_description/meshes/propeller.STL"/>
      </geometry>
    </collision>
  </link>
  <link name="front_right_prop">
    <inertial>
      <origin rpy="0 0 0" xyz="0 0 0.0089339"/>
      <mass value="0.06804"/>
      <inertia ixx="5.4455E-05" ixy="2.3822E-05" ixz="0" iyy="1.2182E-05" iyz="0" izz="6.5653E-05"/>
    </inertial>
    <visual>
      <origin rpy="0 0 0" xyz="0 0 0"/>
      <geometry>
        <mesh filename="package://drone_description/meshes/propeller.STL"/>
      </geometry>
      <material name="">
        <color rgba="0.69804 0.69804 0.69804 1"/>
      </material>
    </visual>
    <collision>
      <origin rpy="0 0 0" xyz="0 0 0"/>
      <geometry>
        <mesh filename="package://drone_description/meshes/propeller.STL"/>
      </geometry>
    </collision>
  </link>
  <link name="back_left_prop">
    <inertial>
      <origin rpy="0 0 0" xyz="0 0 0.0089339"/>
      <mass value="0.06804"/>
      <inertia ixx="5.4455E-05" ixy="2.3822E-05" ixz="0" iyy="1.2182E-05" iyz="0" izz="6.5653E-05"/>
    </inertial>
    <visual>
      <origin rpy="0 0 0" xyz="0 0 0"/>
      <geometry>
        <mesh filename="package://drone_description/meshes/propeller.STL"/>
      </geometry>
      <material name="">
        <color rgba="0.69804 0.69804 0.69804 1"/>
      </material>
    </visual>
    <collision>
      <origin rpy="0 0 0" xyz="0 0 0"/>
      <geometry>
        <mesh filename="package://drone_description/meshes/propeller.STL"/>
      </geometry>
    </collision>
  </link>
  <link name="back_right_prop">
    <inertial>
      <origin rpy="0 0 0" xyz="0 0 0.0089339"/>
      <mass value="0.06804"/>
      <inertia ixx="5.4455E-05" ixy="2.3822E-05" ixz="0" iyy="1.2182E-05" iyz="0" izz="6.5653E-05"/>
    </inertial>
    <visual>
      <origin rpy="0 0 0" xyz="0 0 0"/>
      <geometry>
        <mesh filename="package://drone_description/meshes/propeller.STL"/>
      </geometry>
      <material name="">
        <color rgba="0.69804 0.69804 0.69804 1"/>
      </material>
    </visual>
    <collision>
      <origin rpy="0 0 0" xyz="0 0 0"/>
      <geometry>
        <mesh filename="package://drone_description/meshes/propeller.STL"/>
      </geometry>
    </collision>
  </link>
  <joint name="front_left_prop_joint" type="continuous">
    <origin rpy="0 0 0" xyz="-0.092959 0.073449 0.0385"/>
    <parent link="base_link"/>
    <child link="front_left_prop"/>
    <axis xyz="0 0 1"/>
  </joint>
  <joint name="front_right_prop_joint" type="continuous">
    <origin rpy="0 0 0" xyz="0.092959 0.073449 0.0385"/>
    <parent link="base_link"/>
    <child link="front_right_prop"/>
    <axis xyz="0 0 -1"/>
  </joint>
  <joint name="back_left_prop_joint" type="continuous">
    <origin rpy="0 0 0" xyz="-0.093338 -0.10988 0.0385"/>
    <parent link="base_link"/>
    <child link="back_left_prop"/>
    <axis xyz="0 0 -1"/>
  </joint>
  <joint name="back_right_prop_joint" type="continuous">
    <origin rpy="0 0 0" xyz="0.093338 -0.10988 0.0385"/>
    <parent link="base_link"/>
    <child link="back_right_prop"/>
    <axis xyz="0 0 1"/>
  </joint>
  <transmission name="front_left_prop_trans">
    <type>transmission_interface/SimpleTransmission</type>
    <joint name="front_left_prop_joint">
      <hardwareInterface>hardware_interface/VelocityJointInterface</hardwareInterface>
    </joint>
    <actuator name="front_left_prop_motor">
      <mechanicalReduction>1</mechanicalReduction>
      <hardwareInterface>hardware_interface/VelocityJointInterface</hardwareInterface>
    </actuator>
  </transmission>
  <transmission name="front_right_prop_trans">
    <type>transmission_interface/SimpleTransmission</type>
    <joint name="front_right_prop_joint">
      <hardwareInterface>hardware_interface/VelocityJointInterface</hardwareInterface>
    </joint>
    <actuator name="front_right_prop_motor">
      <mechanicalReduction>1</mechanicalReduction>
      <hardwareInterface>hardware_interface/VelocityJointInterface</hardwareInterface>
    </actuator>
  </transmission>
  <transmission name="back_left_prop_trans">
    <type>transmission_interface/SimpleTransmission</type>
    <joint name="back_left_prop_joint">
      <hardwareInterface>hardware_interface/VelocityJointInterface</hardwareInterface>
    </joint>
    <actuator name="back_left_prop_motor">
      <mechanicalReduction>1</mechanicalReduction>
      <hardwareInterface>hardware_interface/VelocityJointInterface</hardwareInterface>
    </actuator>
  </transmission>
  <transmission name="back_right_prop_trans">
    <type>transmission_interface/SimpleTransmission</type>
    <joint name="back_right_prop_joint">
      <hardwareInterface>hardware_interface/VelocityJointInterface</hardwareInterface>
    </joint>
    <actuator name="back_right_prop_motor">
      <mechanicalReduction>1</mechanicalReduction>
      <hardwareInterface>hardware_interface/VelocityJointInterface</hardwareInterface>
    </actuator>
  </transmission>
  <gazebo>
    <plugin filename="libliftDragPlugin.so" name="front_left_prop_lift">
      <a0>0.1</a0>
      <cla>0.1</cla>
      <cda>0.01</cda>
      <cma>0.0</cma>
      <alpha_stall>0.3368</alpha_stall>
      <cla_stall>-2.1419</cla_stall>
      <cda_stall>0.0</cda_stall>
      <cma_stall>0.0</cma_stall>
      <cp>0 0.5 0</cp>
      <area>0.01</area>
      <air_density>1.2041</air_density>
      <forward>-1 0 0</forward>
      <upward>0 0 1</upward>
      <link_name>front_left_prop</link_name>
      <control_joint>front_left_prop_joint</control_joint>
    </plugin>
  </gazebo>
  <gazebo>
    <plugin filename="libliftDragPlugin.so" name="front_right_prop_lift">
      <a0>0.1</a0>
      <cla>0.1</cla>
      <cda>0.01</cda>
      <cma>0.0</cma>
      <alpha_stall>0.3368</alpha_stall>
      <cla_stall>-2.1419</cla_stall>
      <cda_stall>0.0</cda_stall>
      <cma_stall>0.0</cma_stall>
      <cp>0 0.5 0</cp>
      <area>0.01</area>
      <air_density>1.2041</air_density>
      <forward>-1 0 0</forward>
      <upward>0 0 -1</upward>
      <link_name>front_right_prop</link_name>
      <control_joint>front_right_prop_joint</control_joint>
    </plugin>
  </gazebo>
  <gazebo>
    <plugin filename="libliftDragPlugin.so" name="back_left_prop_lift">
      <a0>0.1</a0>
      <cla>0.1</cla>
      <cda>0.01</cda>
      <cma>0.0</cma>
      <alpha_stall>0.3368</alpha_stall>
      <cla_stall>-2.1419</cla_stall>
      <cda_stall>0.0</cda_stall>
      <cma_stall>0.0</cma_stall>
      <cp>0 0.5 0</cp>
      <area>0.01</area>
      <air_density>1.2041</air_density>
      <forward>-1 0 0</forward>
      <upward>0 0 -1</upward>
      <link_name>back_left_prop</link_name>
      <control_joint>back_left_prop_joint</control_joint>
    </plugin>
  </gazebo>
  <gazebo>
    <plugin filename="libLiftDragPlugin.so" name="back_right_prop_lift">
      <a0>0.1</a0>
      <cla>0.1</cla>
      <cda>0.01</cda>
      <cma>0.0</cma>
      <alpha_stall>0.3368</alpha_stall>
      <cla_stall>-2.1419</cla_stall>
      <cda_stall>0.0</cda_stall>
      <cma_stall>0.0</cma_stall>
      <cp>0 0.5 0</cp>
      <area>0.01</area>
      <air_density>1.2041</air_density>
      <forward>-1 0 0</forward>
      <upward>0 0 1</upward>
      <link_name>back_right_prop</link_name>
      <control_joint>back_right_prop_joint</control_joint>
    </plugin>
  </gazebo>
</robot>
